 <robot xmlns:xacro="http://www.ros.org/wiki/xacro" name="bumperbot">
    
    <xacro:include filename="inertial_macros.xacro"/>
    
    <link name="base_footprint" />

    <link name="base_link">
        <visual>
            <origin rpy="0.0 0.0 0.0" xyz="0.0 0.0 0.0"/>
            <geometry>
                <mesh filename="package://bumperbot_description/meshes/base_link.STL"/>
            </geometry>
        </visual>
        <collision>            
            <origin rpy="0.0 0.0 0.0" xyz="0.0 0.0 0.0"/>
            <geometry>
                <mesh filename="package://bumperbot_description/meshes/base_link.STL"/>
            </geometry>
        </collision>
        <xacro:inertial_box mass="0.5" x="0.12" y="0.12" z="0.12">
            <origin xyz="0 0 0" rpy="0 0 0" />
        </xacro:inertial_box>
    </link>

    <joint name="base_joint" type="fixed">
        <parent link="base_footprint"/>
        <child link="base_link"/>
        <origin rpy="0 0 0" xyz="0 0 0.033"/>
    </joint>

    <link name="wheel_right_link">
        <visual>
            <origin rpy="${pi/2} 0 0" xyz="0 0 0"/>
            <geometry>
                <mesh filename="package://bumperbot_description/meshes/wheel_right_link.STL"/>
            </geometry>
        </visual>
        <collision>
            <origin xyz="0 -0.015 0 " rpy="${pi/2} 0 0" />
            <geometry>
                <sphere radius="0.033"/>
            </geometry>
        </collision>
        <xacro:inertial_cylinder mass="0.1" length="0.04" radius="0.05">
            <origin xyz="0 -0.015 0 " rpy="${pi/2} 0 0" />
        </xacro:inertial_cylinder>
    </link>

    <joint name="wheel_right_joint" type="continuous">
        <parent link="base_link"/>
        <child link="wheel_right_link"/>
        <axis xyz="0 1 0"/>
        <origin xyz="0.0 -0.07 0.0" rpy="0.0 0.0 0.0"/>
    </joint>

    <link name="wheel_left_link">
        <visual>
            <origin rpy="-${pi/2} 0 0" xyz="0 0 0"/>
            <geometry>
                <mesh filename="package://bumperbot_description/meshes/wheel_left_link.STL"/>
            </geometry>
        </visual>
        <collision>
            <origin xyz="0 0.015 0 " rpy="${pi/2} 0 0" />
            <geometry>
                <sphere radius="0.033"/>
            </geometry>    
        </collision>
        <xacro:inertial_cylinder mass="0.1" length="0.04" radius="0.05">
            <origin xyz="0 -0.015 0 " rpy="${pi/2} 0 0" />
        </xacro:inertial_cylinder>
    </link>

    <joint name="wheel_left_joint" type="continuous">
        <parent link="base_link"/>
        <child link="wheel_left_link"/>
        <axis xyz="0 1 0"/>
        <origin xyz="0.0 0.07 0.0" rpy="0.0 0.0 0.0"/>
    </joint>

    <link name="caster_front_link">
        <visual>
            <origin rpy="0 0 0" xyz="0 0 0"/>
            <geometry>
                <mesh filename="package://bumperbot_description/meshes/caster_front_link.STL"/>
            </geometry>
        </visual>
        <collision>
            <origin xyz="0 0 0" rpy="0 0 0" />
            <geometry>
                <sphere radius="0.005" />
            </geometry>    
        </collision>
        <xacro:inertial_sphere mass="0.1" radius="0.005">
            <origin xyz="0 0 0" rpy="0 0 0" />
        </xacro:inertial_sphere>
    </link>

    <joint name="caster_front_joint" type="fixed">
        <parent link="base_link"/>
        <child link="caster_front_link"/>
        <origin xyz="0.047 0 -0.027" rpy="0 0 0"/>
    </joint>

    <link name="caster_rear_link">
        <visual>
            <origin rpy="0 0 0" xyz="0 0 0"/>
            <geometry>
                <mesh filename="package://bumperbot_description/meshes/caster_rear_link.STL"/>
            </geometry>
        </visual>
        <collision>
            <origin xyz="0 0 0" rpy="0 0 0" />
            <geometry>
                <sphere radius="0.005" />
            </geometry>    
        </collision>
        <xacro:inertial_sphere mass="0.1" radius="0.005">
            <origin xyz="0 0 0" rpy="0 0 0" />
        </xacro:inertial_sphere>
    </link>

    <joint name="caster_rear_joint" type="fixed">
        <parent link="base_link"/>
        <child link="caster_rear_link"/>
        <origin xyz="-0.047 0 -0.027" rpy="0 0 0"/>
    </joint>
 </robot>
